Workbook

Sheet Dashboard
A1: 📊 FINANCIAL STATEMENT ANALYSIS — DASHBOARD
A2: Food & Beverage Sector | Mondelez · PepsiCo · Hershey | FY2022–FY2025 Actuals
A4: KEY FINANCIALS — FY2025 ACTUALS
A5: Metric | B5: Mondelez | C5: PepsiCo | D5: Hershey
A6: Total Revenue | B6: =Mondelez!E3 -> 38537000 | C6: =Pepsico!E3 -> 93925000 | D6: =Hershey!E3 -> 11692576
A7: Gross Profit | B7: =Mondelez!E6 -> 10935000 | C7: =Pepsico!E6 -> 50859000 | D7: =Hershey!E6 -> 3922691
A8: Operating Income | B8: =Mondelez!E13 -> 3620000 | C8: =Pepsico!E9 -> 13491000 | D8: =Hershey!E12 -> 1462122
A9: Net Income | B9: =Mondelez!E29 -> 2451000 | C9: =Pepsico!E20 -> 8240000 | D9: =Hershey!E25 -> 883259
A10: EBITDA | B10: =Mondelez!E45 -> 4971000 | C10: =Pepsico!E36 -> 15543000 | D10: =Hershey!E42 -> 1942715
A11: Total Assets | B11: =Mondelez!O3 -> 71487000 | C11: =Pepsico!O3 -> 107399000 | D11: =Hershey!O3 -> 13741297
A12: Total Equity | B12: =Mondelez!O53 -> 25891000 | C12: =Pepsico!O56 -> 20547000 | D12: =Hershey!O53 -> 4636750
A14: PROFITABILITY MARGINS — FY2025
A15: Metric | B15: Mondelez | C15: PepsiCo | D15: Hershey | E15: Unit
A16: Gross Margin | B16: =Mondelez!E6/Mondelez!E3 -> 0.28375328 | C16: =Pepsico!E6/Pepsico!E3 -> 0.54148523 | D16: =Hershey!E6/Hershey!E3 -> 0.33548561 | E16: %
A17: Operating Margin | B17: =Mondelez!E13/Mondelez!E3 -> 0.093935698 | C17: =Pepsico!E9/Pepsico!E3 -> 0.14363588 | D17: =Hershey!E12/Hershey!E3 -> 0.12504704 | E17: %
A18: Net Profit Margin | B18: =Mondelez!E29/Mondelez!E3 -> 0.063601214 | C18: =Pepsico!E20/Pepsico!E3 -> 0.087729571 | D18: =Hershey!E25/Hershey!E3 -> 0.075540155 | E18: %
A19: EBITDA Margin | B19: =Mondelez!E45/Mondelez!E3 -> 0.12899292 | C19: =Pepsico!E36/Pepsico!E3 -> 0.1654831 | D19: =Hershey!E42/Hershey!E3 -> 0.16614944 | E19: %
A21: REVENUE PROJECTIONS SUMMARY ($000)
A22: Company | B22: FY2026 | C22: FY2027 | D22: FY2028 | E22: CAGR
A23: Mondelez | B23: ='Financial Projections'!B14 -> 40463850 | C23: ='Financial Projections'!C14 -> 42487042 | D23: ='Financial Projections'!D14 -> 44611395 | E23: 5.0%
A24: PepsiCo | B24: ='Financial Projections'!F14 -> 96742750 | C24: ='Financial Projections'!G14 -> 99645032 | D24: ='Financial Projections'!H14 -> 1.0263438e+08 | E24: 3.0%
A25: Hershey | B25: ='Financial Projections'!J14 -> 12160279 | C25: ='Financial Projections'!K14 -> 12646690 | D25: ='Financial Projections'!L14 -> 13152558 | E25: 4.0%
B70: Gross Margin | C70: Operating Margin | D70: Net Margin
A71: Mondelez | B71: =Mondelez!E6/Mondelez!E3 -> 0.28375328 | C71: =Mondelez!E13/Mondelez!E3 -> 0.093935698 | D71: =Mondelez!E29/Mondelez!E3 -> 0.063601214
A72: PepsiCo | B72: =Pepsico!E6/Pepsico!E3 -> 0.54148523 | C72: =Pepsico!E9/Pepsico!E3 -> 0.14363588 | D72: =Pepsico!E20/Pepsico!E3 -> 0.087729571
A73: Hershey | B73: =Hershey!E6/Hershey!E3 -> 0.33548561 | C73: =Hershey!E12/Hershey!E3 -> 0.12504704 | D73: =Hershey!E25/Hershey!E3 -> 0.075540155

Sheet Mondelez
A1: Income Statement | K1: Balance Sheet | U1: Cashflow
A2: Particulars | B2: 2022 | C2: 2023 | D2: 2024 | E2: 2025 | K2: Particulars | L2: 2022 | M2: 2023 | N2: 2024 | O2: 2025 | U2: Particulars | V2: 2022 | W2: 2023 | X2: 2024 | Y2: 2025
A3: Total Revenue | B3: 31496000 | C3: 36016000 | D3: 36441000 | E3: 38537000 | K3: Total Assets | L3: 71161000 | M3: 71391000 | N3: 68497000 | O3: 71487000 | U3: Operating Cash Flow | V3: 3908000 | W3: 4714000 | X3: 4910000 | Y3: 4514000
A4: Operating Revenue | B4: 31496000 | C4: 36016000 | D4: 36441000 | E4: 38537000 | K4: Current Assets | L4: 10091000 | M4: 11703000 | N4: 13242000 | O4: 12951000 | U4: Cash Flow from Continuing Operating Activities | V4: 3908000 | W4: 4714000 | X4: 4910000 | Y4: 4514000
A5: Cost of Revenue | B5: 20184000 | C5: 22252000 | D5: 22184000 | E5: 27602000 | K5: Cash, Cash Equivalents & Short Term Investments | L5: 1923000 | M5: 1810000 | N5: 1351000 | O5: 2125000 | U5: Net Income from Continuing Operations | V5: 2726000 | W5: 4968000 | X5: 4623000 | Y5: 2466000
A6: Gross Profit | B6: 11312000 | C6: 13764000 | D6: 14257000 | E6: 10935000 | K6: Cash And Cash Equivalents | L6: 1923000 | M6: 1810000 | N6: 1351000 | O6: 2125000 | U6: Operating Gains Losses | V6: -25000 | W6: -1497000 | X6: -469000 | Y6: 1301000
A7: Operating Expense | B7: 7516000 | C7: 8153000 | D7: 7592000 | E7: 7315000 | K7: Receivables | L7: 3907000 | M7: 4512000 | N7: 4811000 | O7: 4858000 | U7: Gain Loss On Sale of Business | V7: 0 | W7: -108000 | X7: -4000 | Y7: -13000
A8: Selling General and Administrative | B8: 7384000 | C8: 8002000 | D8: 7439000 | E8: 7173000 | K8: Accounts Receivable | L8: 3088000 | M8: 3634000 | N8: 3874000 | O8: 3903000 | U8: Gain Loss On Investment Securities | V8: 338000 | W8: -764000 | X8: -627000 | Y8: 1379000
A9: Depreciation Amortization Depletion | B9: 132000 | C9: 151000 | D9: 153000 | E9: 142000 | K9: Gross Accounts Receivable | L9: 3133000 | M9: 3700000 | N9: 3911000 | O9: 3938000 | U9: Earnings Losses from Equity Investments | V9: -363000 | W9: -625000 | X9: 162000 | Y9: -65000
A10: Depreciation & Amortization | B10: 132000 | C10: 151000 | D10: 153000 | E10: 142000 | K10: Allowance for Doubtful Accounts | L10: -45000 | M10: -66000 | N10: -37000 | O10: -35000 | U10: Depreciation Amortization Depletion | V10: 1107000 | W10: 1215000 | X10: 1302000 | Y10: 1358000
A11: Amortization | B11: 132000 | C11: 151000 | D11: 153000 | E11: 142000 | K11: Other Receivables | L11: 819000 | M11: 878000 | N11: 937000 | O11: 955000 | U11: Depreciation & Amortization | V11: 1107000 | W11: 1215000 | X11: 1302000 | Y11: 1358000
A12: Amortization of Intangibles | B12: 132000 | C12: 151000 | D12: 153000 | E12: 142000 | K12: Inventory | L12: 3381000 | M12: 3615000 | N12: 3827000 | O12: 4419000 | U12: Deferred Tax | V12: -42000 | W12: -37000 | X12: 257000 | Y12: 16000
A13: Operating Income | B13: 3796000 | C13: 5611000 | D13: 6665000 | E13: 3620000 | K13: Raw Materials | L13: 1031000 | M13: 973000 | N13: 958000 | O13: 1015000 | U13: Deferred Income Tax | V13: -42000 | W13: -37000 | X13: 257000 | Y13: 16000
A14: Total Operating Income as Reported | B14: 3534000 | C14: 5502000 | D14: 6345000 | E14: 3548000 | K14: Finished Goods | L14: 2501000 | M14: 2790000 | N14: 2869000 | O14: 3404000 | U14: Asset Impairment Charge | V14: 233000 | W14: 128000 | X14: 267000 | Y14: 85000
A15: Net Non Operating Interest Income Expense | B15: -294000 | C15: -309000 | D15: -180000 | E15: -282000 | K15: Inventory Adjustments | L15: -151000 | M15: -148000 | N15: -171000 | O15: — | U15: Stock Based Compensation | V15: 120000 | W15: 146000 | X15: 147000 | Y15: 114000
A16: Interest Income Non Operating | B16: 134000 | C16: 241000 | D16: 328000 | E16: 317000 | K16: Other Current Assets | L16: 880000 | M16: 1766000 | N16: 3253000 | O16: 1549000 | U16: Other Non-Cash Items | V16: 118000 | W16: 163000 | X16: -363000 | Y16: 103000
A17: Interest Expense Non Operating | B17: 428000 | C17: 550000 | D17: 508000 | E17: 599000 | K17: Total Non-Current Assets | L17: 61070000 | M17: 59688000 | N17: 55255000 | O17: 58536000 | U17: Change in Working Capital | V17: -513000 | W17: -509000 | X17: -969000 | Y17: -974000
A18: Other Income Expense | B18: -274000 | C18: 578000 | D18: -224000 | E18: -324000 | K18: Net PPE | L18: 9680000 | M18: 10377000 | N18: 10248000 | O18: 11398000 | U18: Change in Receivables | V18: -719000 | W18: -628000 | X18: -519000 | Y18: 433000
A19: Gain on Sale of Security | B19: — | C19: 606000 | D19: — | E19: — | K19: Gross PPE | L19: 16891000 | M19: 18373000 | N19: 18383000 | O19: 20793000 | U19: Change in Inventory | V19: -635000 | W19: -193000 | X19: -458000 | Y19: -253000
A20: Special Income Charges | B20: -391000 | C20: -110000 | D20: -320000 | E20: -72000 | K20: Land & Improvements | L20: 378000 | M20: 384000 | N20: 373000 | O20: 404000 | U20: Change in Payables And Accrued Expense | V20: 715000 | W20: 264000 | X20: 1682000 | Y20: -145000
A21: Restructuring & Mergers Acquisition | B21: 0 | C21: -108000 | D21: -4000 | E21: -13000 | K21: Buildings & Improvements | L21: 3250000 | M21: 3452000 | N21: 3453000 | O21: 3963000 | U21: Change in Payable | V21: 715000 | W21: 264000 | X21: 1682000 | Y21: -145000
A22: Impairment of Capital Assets | B22: 262000 | C22: 217000 | D22: 324000 | E22: 85000 | K22: Machinery, Furniture, Equipment | L22: 11724000 | M22: 12736000 | N22: 12732000 | O22: 14610000 | U22: Change in Account Payable | V22: 715000 | W22: 264000 | X22: 1682000 | Y22: -145000
A23: Other Special Charges | B23: 129000 | C23: 1000 | D23: — | E23: — | K23: Other Properties | L23: 660000 | M23: 683000 | N23: 767000 | O23: 731000 | U23: Change in Other Current Assets | V23: -286000 | W23: -120000 | X23: -591000 | Y23: -225000
A24: Other Non Operating Income Expenses | B24: 117000 | C24: 82000 | D24: 96000 | E24: -252000 | K24: Construction in Progress | L24: 879000 | M24: 1118000 | N24: 1058000 | O24: 1085000 | U24: Change in Other Current Liabilities | V24: 638000 | W24: 354000 | X24: -932000 | Y24: -1026000
A25: Pretax Income | B25: 3228000 | C25: 5880000 | D25: 6261000 | E25: 3014000 | K25: Accumulated Depreciation | L25: -7211000 | M25: -7996000 | N25: -8135000 | O25: -9395000 | U25: Change in Other Working Capital | V25: -226000 | W25: -186000 | X25: -151000 | Y25: 242000
A26: Tax Provision | B26: 865000 | C26: 1537000 | D26: 1469000 | E26: 782000 | K26: Goodwill & Intangible Assets | L26: 43160000 | M26: 43732000 | N26: 41865000 | O26: 43964000 | U26: Dividend Received CFO | V26: 184000 | W26: 137000 | X26: 115000 | Y26: 45000
A27: Earnings from Equity Interest Net of Tax | B27: 363000 | C27: 625000 | D27: -169000 | E27: 234000 | K27: Goodwill | L27: 23450000 | M27: 23896000 | N27: 23017000 | O27: 24336000 | U27: Investing Cash Flow | V27: -4888000 | W27: 2812000 | X27: 526000 | Y27: -1196000
A28: Net Income Common Stockholders | B28: 2717000 | C28: 4959000 | D28: 4611000 | E28: 2451000 | K28: Other Intangible Assets | L28: 19710000 | M28: 19836000 | N28: 18848000 | O28: 19628000 | U28: Cash Flow from Continuing Investing Activities | V28: -4888000 | W28: 2812000 | X28: 526000 | Y28: -1196000
A29: Net Income | B29: 2717000 | C29: 4959000 | D29: 4611000 | E29: 2451000 | K29: Investments & Advances | L29: 4879000 | M29: 3242000 | N29: 635000 | O29: 667000 | U29: Capital Expenditure Reported | V29: -906000 | W29: -1112000 | X29: -1387000 | Y29: -1279000
A30: Net Income Including Non-Controlling Interests | B30: 2726000 | C30: 4968000 | D30: 4623000 | E30: 2466000 | K30: Long Term Equity Investment | L30: 4879000 | M30: 3242000 | N30: 635000 | O30: 667000 | U30: Net PPE Purchase And Sale | V30: 45000 | W30: 19000 | X30: 16000 | Y30: 9000
A31: Net Income Continuous Operations | B31: 2726000 | C31: 4968000 | D31: 4623000 | E31: 2466000 | K31: Non-Current Deferred Assets | L31: 473000 | M31: 408000 | N31: 333000 | O31: 336000 | U31: Sale of PPE | V31: 45000 | W31: 19000 | X31: 16000 | Y31: 9000
A32: Minority Interests | B32: -9000 | C32: -9000 | D32: -12000 | E32: -15000 | K32: Deferred Tax Assets | L32: 473000 | M32: 408000 | N32: 333000 | O32: 336000 | U32: Net Business Purchase And Sale | V32: -4685000 | W32: 4118000 | X32: 2054000 | Y32: 112000
A33: Diluted NI Available to Com Stockholders | B33: 2717000 | C33: 4959000 | D33: 4611000 | E33: 2451000 | K33: Non Current Prepaid Assets | L33: 1016000 | M33: 1043000 | N33: — | O33: — | U33: Purchase of Business | V33: -5286000 | W33: -309000 | X33: -240000 | Y33: -15000
A34: Basic EPS | B34: 1.97 | C34: 3.64 | D34: 3.44 | E34: 1.89 | K34: Defined Pension Benefit | L34: 1016000 | M34: 1043000 | N34: 987000 | O34: 1220000 | U34: Sale of Business | V34: 601000 | W34: 4118000 | X34: 2294000 | Y34: 127000
A35: Diluted EPS | B35: 1.96 | C35: 3.62 | D35: 3.42 | E35: 1.89 | K35: Other Non Current Assets | L35: 1862000 | M35: 886000 | N35: 1187000 | O35: 951000 | U35: Net Investment Purchase And Sale | V35: 658000 | W35: -213000 | X35: -157000 | Y35: -38000
A36: Basic Average Shares | B36: 1378000 | C36: 1363000 | D36: 1341000 | E36: 1294000 | K36: Total Liabilities | L36: 44241000 | M36: 43025000 | N36: 41539000 | O36: 45596000 | U36: Purchase of Investment | V36: -110000 | W36: -390000 | X36: -477000 | Y36: -165000
A37: Diluted Average Shares | B37: 1385000 | C37: 1370000 | D37: 1347000 | E37: 1298000 | K37: Current Liabilities | L37: 16731000 | M37: 19013000 | N37: 19549000 | O37: 21864000 | U37: Sale of Investment | V37: 768000 | W37: 177000 | X37: 320000 | Y37: 127000
A38: Total Expenses | B38: 27700000 | C38: 30405000 | D38: 29776000 | E38: 34917000 | K38: Payables & Accrued Expenses | L38: 9932000 | M38: 11004000 | N38: 11991000 | O38: 12926000 | U38: Financing Cash Flow | V38: -456000 | W38: -7558000 | X38: -5780000 | Y38: -2759000
A39: Net Income from Continuing & Discontinued Operation | B39: 2717000 | C39: 4959000 | D39: 4611000 | E39: 2451000 | K39: Accounts Payable | L39: 7562000 | M39: 8321000 | N39: 9433000 | O39: 10139000 | U39: Cash Flow from Continuing Financing Activities | V39: -456000 | W39: -7558000 | X39: -5780000 | Y39: -2759000
A40: Normalized Income | B40: 3003212 | C40: 4592456 | D40: 4855919 | E40: 2504319 | K40: Current Accrued Expenses | L40: 2370000 | M40: 2683000 | N40: 2558000 | O40: 2787000 | U40: Net Issuance Payments of Debt | V40: 3372000 | W40: -4024000 | X40: -1226000 | Y40: 2126000
...

Sheet Pepsico
A1: Income Statement | K1: Balance Sheet | U1: Cashflow
A2: Particulars | B2: 2022 | C2: 2023 | D2: 2024 | E2: 2025 | K2: Particulars | L2: 2022 | M2: 2023 | N2: 2024 | O2: 2025 | U2: Particulars | V2: 2022 | W2: 2023 | X2: 2024 | Y2: 2025
A3: Total Revenue | B3: 86392000 | C3: 91471000 | D3: 91854000 | E3: 93925000 | K3: Total Assets | L3: 92187000 | M3: 100495000 | N3: 99467000 | O3: 107399000 | U3: Operating Cash Flow | V3: 10811000 | W3: 13442000 | X3: 12507000 | Y3: 12087000
A4: Operating Revenue | B4: 86392000 | C4: 91471000 | D4: 91854000 | E4: 93925000 | K4: Current Assets | L4: 21539000 | M4: 26950000 | N4: 25826000 | O4: 27949000 | U4: Cash Flow from Continuing Operating Activities | V4: 10811000 | W4: 13442000 | X4: 12507000 | Y4: 12087000
A5: Cost of Revenue | B5: 40576000 | C5: 41881000 | D5: 41744000 | E5: 43066000 | K5: Cash, Cash Equivalents & Short Term Investments | L5: 5348000 | M5: 10003000 | N5: 9266000 | O5: 9530000 | U5: Net Income from Continuing Operations | V5: 8978000 | W5: 9155000 | X5: 9626000 | Y5: 8295000
A6: Gross Profit | B6: 45816000 | C6: 49590000 | D6: 50110000 | E6: 50859000 | K6: Cash And Cash Equivalents | L6: 4954000 | M6: 9711000 | N6: 8505000 | O6: 9159000 | U6: Operating Gains Losses | V6: -2902000 | W6: 150000 | X6: 414000 | Y6: 504000
A7: Operating Expense | B7: 34459000 | C7: 36677000 | D7: 37190000 | E7: 37368000 | K7: Other Short Term Investments | L7: 394000 | M7: 292000 | N7: 761000 | O7: 371000 | U7: Gain Loss On Sale of Business | V7: -3321000 | W7: 0 | X7: 0 | Y7: —
A8: Selling General and Administrative | B8: 34459000 | C8: 36677000 | D8: 37190000 | E8: 37368000 | K8: Receivables | L8: 10163000 | M8: 10815000 | N8: 10333000 | O8: 11506000 | U8: Pension and Employee Benefit Expense | V8: 419000 | W8: 150000 | X8: 414000 | Y8: 504000
A9: Operating Income | B9: 11357000 | C9: 12913000 | D9: 12920000 | E9: 13491000 | K9: Accounts Receivable | L9: 8192000 | M9: 8675000 | N9: 8487000 | O9: 9265000 | U9: Depreciation Amortization Depletion | V9: 3280000 | W9: 3518000 | X9: 3815000 | Y9: 4178000
A10: Net Non Operating Interest Income Expense | B10: -939000 | C10: -819000 | D10: -919000 | E10: -1121000 | K10: Other Receivables | L10: 2121000 | M10: 2315000 | N10: 2202000 | O10: 2471000 | U10: Depreciation & Amortization | V10: 3280000 | W10: 3518000 | X10: 3815000 | Y10: 4178000
A11: Interest Expense Non Operating | B11: 939000 | C11: 819000 | D11: 919000 | E11: 1121000 | K11: Receivables Adjustments Allowances | L11: -150000 | M11: -175000 | N11: -356000 | O11: -230000 | U11: Depreciation | V11: 3280000 | W11: 3518000 | X11: 3815000 | Y11: 4178000
A12: Other Income Expense | B12: 287000 | C12: -677000 | D12: -55000 | E12: -2126000 | K12: Inventory | L12: 5222000 | M12: 5334000 | N12: 5306000 | O12: 5845000 | U12: Deferred Tax | V12: -787000 | W12: -271000 | X12: -42000 | Y12: 71000
A13: Special Income Charges | B13: 155000 | C13: -927000 | D13: -33000 | E13: -1993000 | K13: Raw Materials | L13: 2366000 | M13: 2388000 | N13: 2440000 | O13: 2581000 | U13: Deferred Income Tax | V13: -787000 | W13: -271000 | X13: -42000 | Y13: 71000
A14: Restructuring & Mergers Acquisition | B14: -3321000 | C14: 0 | D14: 0 | E14: — | K14: Work in Process | L14: 114000 | M14: 104000 | N14: 104000 | O14: 143000 | U14: Asset Impairment Charge | V14: 3651000 | W14: 1230000 | X14: 714000 | Y14: 1946000
A15: Impairment of Capital Assets | B15: 3166000 | C15: 927000 | D15: 33000 | E15: 1993000 | K15: Finished Goods | L15: 2742000 | M15: 2842000 | N15: 2762000 | O15: 3121000 | U15: Stock Based Compensation | V15: 343000 | W15: 380000 | X15: 362000 | Y15: 288000
A16: Other Non Operating Income Expenses | B16: 132000 | C16: 250000 | D16: -22000 | E16: -133000 | K16: Prepaid Assets | L16: 806000 | M16: — | N16: — | O16: — | U16: Other Non-Cash Items | V16: -555000 | W16: -74000 | X16: -325000 | Y16: -778000
A17: Pretax Income | B17: 10705000 | C17: 11417000 | D17: 11946000 | E17: 10244000 | K17: Assets Held for Sale Current | L17: 0 | M17: — | N17: — | O17: — | U17: Change in Working Capital | V17: -888000 | W17: -337000 | X17: -1478000 | Y17: -1645000
A18: Tax Provision | B18: 1727000 | C18: 2262000 | D18: 2320000 | E18: 1949000 | K18: Other Current Assets | L18: 806000 | M18: 798000 | N18: 921000 | O18: 1068000 | U18: Change in Receivables | V18: -1763000 | W18: -793000 | X18: -138000 | Y18: -580000
A19: Net Income Common Stockholders | B19: 8910000 | C19: 9074000 | D19: 9578000 | E19: 8240000 | K19: Total Non-Current Assets | L19: 70648000 | M19: 73545000 | N19: 73641000 | O19: 79450000 | U19: Change in Inventory | V19: -1142000 | W19: -261000 | X19: -314000 | Y19: -150000
A20: Net Income | B20: 8910000 | C20: 9074000 | D20: 9578000 | E20: 8240000 | K20: Net PPE | L20: 26664000 | M20: 29944000 | N20: 31391000 | O20: 33650000 | U20: Change in Prepaid Assets | V20: 118000 | W20: -13000 | X20: 40000 | Y20: 195000
A21: Net Income Including Non-Controlling Interests | B21: 8978000 | C21: 9155000 | D21: 9626000 | E21: 8295000 | K21: Gross PPE | L21: 52157000 | M21: 57344000 | N21: 59388000 | O21: 64654000 | U21: Change in Payables & Accrued Expense | V21: 1899000 | W21: 730000 | X21: -1066000 | Y21: -1110000
A22: Net Income Continuous Operations | B22: 8978000 | C22: 9155000 | D22: 9626000 | E22: 8295000 | K22: Land & Improvements | L22: 1142000 | M22: 1159000 | N22: 1136000 | O22: 1110000 | U22: Change in Payable | V22: 1899000 | W22: 730000 | X22: -1066000 | Y22: -1110000
A23: Minority Interests | B23: -68000 | C23: -81000 | D23: -48000 | E23: -55000 | K23: Buildings & Improvements | L23: 10816000 | M23: 11579000 | N23: 11938000 | O23: 13875000 | U23: Change in Tax Payable | V23: 57000 | W23: 310000 | X23: -123000 | Y23: -433000
A24: Diluted NI Available to Com Stockholders | B24: 8910000 | C24: 9074000 | D24: 9578000 | E24: 8240000 | K24: Machinery Furniture Equipment | L24: 33335000 | M24: 36006000 | N24: 36990000 | O24: 41113000 | U24: Change in Income Tax Payable | V24: 57000 | W24: 310000 | X24: -123000 | Y24: -433000
A25: Basic EPS | B25: 6.47 | C25: 6.6 | D25: 6.98 | E25: 6.02 | K25: Other Properties | L25: 2373000 | M25: 2905000 | N25: 3383000 | O25: 3745000 | U25: Change in Account Payable | V25: 1842000 | W25: 420000 | X25: -943000 | Y25: -677000
A26: Diluted EPS | B26: 6.42 | C26: 6.56 | D26: 6.95 | E26: 6 | K26: Construction in Progress | L26: 4491000 | M26: 5695000 | N26: 5941000 | O26: 4811000 | U26: Taxes Refund Paid | V26: -309000 | W26: -309000 | X26: -579000 | Y26: -772000
A27: Basic Average Shares | B27: 1377000 | C27: 1374000 | D27: 1371989 | E27: 1369000 | K27: Accumulated Depreciation | L27: -25493000 | M27: -27400000 | N27: -27997000 | O27: -31004000 | U27: Investing Cash Flow | V27: -2430000 | W27: -5495000 | X27: -5472000 | Y27: -6879000
A28: Diluted Average Shares | B28: 1387000 | C28: 1383000 | D28: 1378000 | E28: 1373000 | K28: Goodwill & Intangible Assets | L28: 33788000 | M28: 32657000 | N28: 32335000 | O28: 33982000 | U28: Cash Flow from Continuing Investing Activities | V28: -2430000 | W28: -5495000 | X28: -5472000 | Y28: -6879000
A29: Total Operating Income as Reported | B29: 11512000 | C29: 11986000 | D29: 12887000 | E29: 11498000 | K29: Goodwill | L29: 18202000 | M29: 17728000 | N29: 17534000 | O29: 18916000 | U29: Capital Expenditure Reported | V29: -5207000 | W29: -5518000 | X29: -5318000 | Y29: -4415000
... A44: Tax Effect of Unusual Items | B44: 24955 | C44: -183546 | D44: -6409 | E44: -379184 | K44: Dividends Payable | L44: 1610000 | M44: 1767000 | N44: 1885000 | O44: 1967000 | U44: Long Term Debt Payments | V44: -4174000 | W44: -3005000 | X44: -3886000 | Y44: -4082000
K45: Current Accrued Expenses | L45: 3637000 | M45: 3523000 | N45: 3458000 | O45: 3512000 | U45: Net Short Term Debt Issuance | V45: -13000 | W45: 2293000 | X45: 539000 | Y45: -359000
K46: Pension & Other Post Retirement Benefit Plans Current | L46: 2519000 | M46: 2687000 | N46: 2256000 | O46: 2230000 | U46: Short Term Debt Issuance | V46: 1969000 | W46: 5428000 | X46: 6178000 | Y46: 7561000
K47: Current Debt | L47: 3414000 | M47: 6510000 | N47: 7082000 | O47: 6861000 | U47: Short Term Debt Payments | V47: -1982000 | W47: -3135000 | X47: -5639000 | Y47: -7920000
K48: Commercial Paper | L48: 0 | M48: 2286000 | N48: 2818000 | O48: 2641000 | U48: Net Common Stock Issuance | V48: -1500000 | W48: -1000000 | X48: -1000000 | Y48: -1000000
K49: Other Current Borrowings | L49: 3414000 | M49: 4224000 | N49: 4264000 | O49: 4220000 | U49: Common Stock Payments | V49: -1500000 | W49: -1000000 | X49: -1000000 | Y49: -1000000
K50: Current Capital Lease Obligation | L50: 483000 | M50: 556000 | N50: 642000 | O50: 719000 | U50: Cash Dividends Paid | V50: -6172000 | W50: -6682000 | X50: -7229000 | Y50: -7638000
K51: Other Current Liabilities | L51: 4390000 | M51: 4969000 | N51: 5216000 | O51: 5771000 | U51: Common Stock Dividend Paid | V51: -6172000 | W51: -6682000 | X51: -7229000 | Y51: -7638000
K52: Non-Current Liabilities | L52: 48129000 | M52: 50211000 | N52: 49760000 | O52: 54088000 | U52: Proceeds from Stock Option Exercised | V52: 138000 | W52: 116000 | X52: 166000 | Y52: 97000
K53: Long Term Debt | L53: 35657000 | M53: 37595000 | N53: 37224000 | O53: 42321000 | U53: Net Other Financing Charges | V53: -179000 | W53: -213000 | X53: -188000 | Y53: -186000
K54: Deferred Tax Liabilities | L54: 4133000 | M54: 3895000 | N54: 3484000 | O54: 3802000 | U54: End Cash Position | V54: 5100000 | W54: 9761000 | X54: 8553000 | Y54: 9204000
...

Sheet Hershey
A1: Income Statement | K1: Balance Sheet | U1: Cashflow
A2: Particulars | B2: 2022 | C2: 2023 | D2: 2024 | E2: 2025 | K2: Particulars | L2: 2022 | M2: 2023 | N2: 2024 | O2: 2025 | U2: Particulars | V2: 2022 | W2: 2023 | X2: 2024 | Y2: 2025
A3: Total Revenue | B3: 10419294 | C3: 11164992 | D3: 11202263 | E3: 11692576 | K3: Total Assets | L3: 10948820 | M3: 11902941 | N3: 12946861 | O3: 13741297 | U3: Operating Cash Flow | V3: 2327837 | W3: 2323190 | X3: 2531596 | Y3: 2277367
A4: Operating Revenue | B4: 10419294 | C4: 11164992 | D4: 11202263 | E4: 11692576 | K4: Current Assets | L4: 2620406 | M4: 2912103 | N4: 3759457 | O4: 3588899 | U4: Cash Flow from Continuing Operating Activities | V4: 2327837 | W4: 2323190 | X4: 2531596 | Y4: 2277367
A5: Cost of Revenue | B5: 5920509 | C5: 6167176 | D5: 5901375 | E5: 7769885 | K5: Cash & Cash Equivalents | L5: 463889 | M5: 401902 | N5: 730746 | O5: 925859 | U5: Net Income from Continuing Operations | V5: 1644817 | W5: 1861787 | X5: 2221239 | Y5: 883259
A6: Gross Profit | B6: 4498785 | C6: 4997816 | D6: 5300888 | E6: 3922691 | K6: Receivables | L6: 711203 | M6: 823617 | N6: 800402 | O6: 729547 | U6: Operating Gains Losses | V6: — | W6: — | X6: -513800 | Y6: 530445
A7: Operating Expense | B7: 2236009 | C7: 2436508 | D7: 2373621 | E7: 2460569 | K7: Accounts Receivable | L7: 711203 | M7: 823617 | N7: 800402 | O7: 729547 | U7: Gain Loss On Investment Securities | V7: — | W7: — | X7: -513800 | Y7: 530445
A8: Selling General and Administrative | B8: 2236009 | C8: 2436508 | D8: 2373621 | E8: 2460569 | K8: Gross Accounts Receivable | L8: 737204 | M8: 855280 | N8: 840889 | O8: 749591 | U8: Depreciation Amortization Depletion | V8: 378959 | W8: 419815 | X8: 455255 | Y8: 503701
A9: General & Administrative Expense | B9: 2254475 | C9: 2464518 | D9: — | E9: — | K9: Allowance for Doubtful Accounts | L9: -26001 | M9: -31663 | N9: -40487 | O9: -20044 | U9: Depreciation & Amortization | V9: 378959 | W9: 419815 | X9: 455255 | Y9: 503701
A10: Salaries and Wages | B10: 18466 | C10: 28010 | D10: — | E10: — | K10: Inventory | L10: 1173119 | M10: 1340996 | N10: 1254094 | O10: 1429254 | U10: Deferred Tax | V10: 36889 | W10: 16233 | X10: 73235 | Y10: 122293
A11: Other G & A | B11: 2236009 | C11: 2436508 | D11: — | E11: — | K11: Raw Materials | L11: 372612 | M11: 481111 | N11: 477592 | O11: 762391 | U11: Deferred Income Tax | V11: 36889 | W11: 16233 | X11: 73235 | Y11: 122293
A12: Operating Income | B12: 2262776 | C12: 2561308 | D12: 2927267 | E12: 1462122 | K12: Work in Process | L12: 137298 | M12: 192232 | N12: 204674 | O12: 294374 | U12: Asset Impairment Charge | V12: 188286 | W12: 210484 | X12: 243311 | Y12: 30886
A13: Net Non Operating Interest Income Expense | B13: -137557 | C13: -151785 | D13: -165655 | E13: -190206 | K13: Finished Goods | L13: 855217 | M13: 948974 | N13: 990785 | O13: 1074690 | U13: Stock Based Compensation | V13: 65991 | W13: 81021 | X13: 44414 | Y13: 65460
A14: Interest Income Non Operating | B14: 2538 | C14: 9726 | D14: 8662 | E14: 34600 | K14: Inventory Adjustments | L14: -192008 | M14: -281321 | N14: -418957 | O14: -702201 | U14: Other Non-Cash Items | V14: 42271 | W14: 75706 | X14: 61005 | Y14: 85560
A15: Interest Expense Non Operating | B15: 140095 | C15: 161511 | D15: 174317 | E15: 224806 | K15: Prepaid Assets | L15: 143888 | M15: 227567 | N15: 269792 | O15: 201527 | U15: Change in Working Capital | V15: -29376 | W15: -341856 | X15: -53063 | Y15: 55763
A16: Other Income Expense | B16: -208148 | C16: -237659 | D16: -287676 | E16: -57708 | K16: Other Current Assets | L16: 128307 | M16: 118021 | N16: 704423 | O16: 302712 | U16: Change in Receivables | V16: -38165 | W16: -102080 | X16: 4456 | Y16: 98968
A17: Special Income Charges | B17: -190275 | C17: -210925 | D17: -272346 | E17: -45077 | K17: Total Non-Current Assets | L17: 8328414 | M17: 8990838 | N17: 9187404 | O17: 10152398 | U17: Changes in Account Receivables | V17: -38165 | W17: -102080 | X17: 4456 | Y17: 98968
A18: Restructuring & Mergers Acquisition | B18: 1989 | C18: 441 | D18: 29035 | E18: 20594 | K18: Net PPE | L18: 3096174 | M18: 3617654 | N18: 3796592 | O18: 3854953 | U18: Change in Inventory | V18: -186963 | W18: -157153 | X18: 68831 | Y18: -133320
A19: Impairment of Capital Assets | B19: 0 | C19: — | D19: — | E19: — | K19: Gross PPE | L19: 6035959 | M19: 6757047 | N19: 7150550 | O19: 7468143 | U19: Change in Prepaid Assets | V19: -14507 | W19: -22444 | X19: -89809 | Y19: -153534
A20: Write Off | B20: 188286 | C20: 210484 | D20: 243311 | E20: 24483 | K20: Land & Improvements | L20: 155963 | M20: 180751 | N20: 194502 | O20: 199559 | U20: Change in Payables And Accrued Expense | V20: 221484 | W20: 17753 | X20: 11808 | Y20: 245690
A21: Other Non Operating Income Expenses | B21: -17873 | C21: -26734 | D21: -15330 | E21: -12631 | K21: Buildings & Improvements | L21: 1545053 | M21: 1763070 | N21: 1991937 | O21: 2102794 | U21: Change in Payable | V21: 221484 | W21: 17753 | X21: 11808 | Y21: 245690
A22: Pretax Income | B22: 1917071 | C22: 2171864 | D22: 2473936 | E22: 1214208 | K22: Machinery, Furniture & Equipment | L22: 3592251 | M22: 3861006 | N22: 4147530 | O22: 4515447 | U22: Change in Tax Payable | V22: 5005 | W22: -32481 | X22: -17093 | Y22: 82195
A23: Tax Provision | B23: 272254 | C23: 310077 | D23: 252697 | E23: 330949 | K23: Other Properties | L23: 326472 | M23: 307976 | N23: 337739 | O23: 325345 | U23: Change in Income Tax Payable | V23: 5005 | W23: -32481 | X23: -17093 | Y23: 82195
A24: Net Income Common Stockholders | B24: 1644817 | C24: 1861787 | D24: 2221239 | E24: 883259 | K24: Construction in Progress | L24: 416220 | M24: 644244 | N24: 478842 | O24: 324998 | U24: Change in Account Payable | V24: 216479 | W24: 50234 | X24: 28901 | Y24: 163495
A25: Net Income | B25: 1644817 | C25: 1861787 | D25: 2221239 | E25: 883259 | K25: Accumulated Depreciation | L25: -2939785 | M25: -3139393 | N25: -3353958 | O25: -3613190 | U25: Change in Other Working Capital | V25: -11225 | W25: -77932 | X25: -48349 | Y25: -2041
A26: Net Income Including Non-Controlling Interests | B26: 1644817 | C26: 1861787 | D26: 2221239 | E26: 883259 | K26: Goodwill & Intangible Assets | L26: 4893259 | M26: 4935484 | N26: 4946706 | O26: 5822988 | U26: Investing Cash Flow | V26: -787376 | W26: -1198676 | X26: -960314 | Y26: -1278717
A27: Net Income Continuous Operations | B27: 1644817 | C27: 1861787 | D27: 2221239 | E27: 883259 | K27: Goodwill | L27: 2606956 | M27: 2696050 | N27: 2705753 | O27: 2996005 | U27: Cash Flow from Continuing Investing Activities | V27: -787376 | W27: -1198676 | X27: -960314 | Y27: -1278717
A28: Minority Interests | B28: 0 | C28: 0 | D28: — | E28: — | K28: Other Intangible Assets | L28: 2286303 | M28: 2239434 | N28: 2240953 | O28: 2826983 | U28: Capital Expenditure Reported | V28: -519481 | W28: -771109 | X28: -605942 | Y28: -454622
A29: Diluted NI Available to Com Stockholders | B29: 1644817 | C29: 1861787 | D29: 2221239 | E29: 883259 | K29: Investments & Advances | L29: 133029 | M29: 207177 | N29: 212928 | O29: 176567 | U29: Net Intangibles Purchase And Sale | V29: — | W29: 0 | X29: 0 | Y29: -73597
A30: Basic EPS | B30: 8.22 | C30: 9.31 | D30: 11.22 | E30: 4.46 | K30: Long Term Equity Investment | L30: 133029 | M30: 207177 | N30: 212928 | O30: 176567 | U30: Purchase of Intangibles | V30: — | W30: 0 | X30: 0 | Y30: -73597
A31: Diluted EPS | B31: 7.96 | C31: 9.06 | D31: 10.92 | E31: 4.34 | K31: Deferred Tax Assets | L31: 40498 | M31: 44454 | N31: 37065 | O31: 27802 | U31: Net Business Purchase And Sale | V31: -275534 | W31: -422633 | X31: -360999 | Y31: -744257
A32: Basic Average Shares | B32: 205535 | C32: 204738 | D32: 202963 | E32: 202895 | K32: Defined Pension Benefit | L32: 53495 | M32: 48506 | N32: 41298 | O32: 64520 | U32: Purchase of Business | V32: -275534 | W32: -165818 | X32: -75500 | Y32: -756135
A33: Diluted Average Shares | B33: 206575 | C33: 205547 | D33: 203487 | E33: 203379 | K33: Other Non Current Assets | L33: 111959 | M33: 137563 | N33: 152815 | O33: 205568 | U33: Net Other Investing Changes | V33: 7639 | W33: -4934 | X33: 6627 | Y33: -6241
A34: Total Operating Income as Reported | B34: 2260787 | C34: 2560867 | D34: 2898232 | E34: 1441528 | K34: Total Liabilities | L34: 7649276 | M34: 7803855 | N34: 8232207 | O34: 9104547 | U34: Financing Cash Flow | V34: -1415725 | W34: -1148251 | X34: -1296501 | Y34: -803357
A35: Total Expenses | B35: 8156518 | C35: 8603684 | D35: 8274996 | E35: 10230454 | K35: Current Liabilities | L35: 3257154 | M35: 3008352 | N35: 3929495 | O35: 3011896 | U35: Cash Flow from Continuing Financing Activities | V35: -1415725 | W35: -1148251 | X35: -1296501 | Y35: -803357
A36: Net Income from Continuing & Discontinued Operation | B36: 1644817 | C36: 1861787 | D36: 2221239 | E36: 883259 | K36: Payables & Accrued Expenses | L36: 1777999 | M36: 1948961 | N36: 1976918 | O36: 2240440 | U36: Net Issuance Payments of Debt | V36: -250374 | W36: 14727 | X36: 300647 | Y36: 279421
A37: Normalized Income | B37: 1808072.9 | C37: 2042549.7 | D37: 2465766.6 | E37: 916049.65 | K37: Payables | L37: 977268 | M37: 1115640 | N37: 1210213 | O37: 1319426 | U37: Net Long Term Debt Issuance | V37: -4741 | W37: -11322 | X37: -306359 | Y37: 1378152
A38: Interest Income | B38: 2538 | C38: 9726 | D38: 8662 | E38: 34600 | K38: Accounts Payable | L38: 970558 | M38: 630536 | N38: 807918 | O38: 831204 | U38: Long Term Debt Issuance | V38: 0 | W38: 744092 | X38: 0 | Y38: 1984545
A39: Interest Expense | B39: 140095 | C39: 161511 | D39: 174317 | E39: 224806 | K39: Income Tax Payable | L39: 6710 | M39: 29457 | N39: 51036 | O39: 63725 | U39: Long Term Debt Payments | V39: -4741 | W39: -755414 | X39: -306359 | Y39: -606393
A40: Net Interest Income | B40: -137557 | C40: -151785 | D40: -165655 | E40: -190206 | K40: Other Payables | L40: — | M40: — | N40: 351259 | O40: 424497 | U40: Net Short Term Debt Issuance | V40: -245633 | W40: 26049 | X40: 607006 | Y40: -1098731
...

Sheet Ratio Analysis
A1: RATIO ANALYSIS
A2: Ratio | B2: Company | C2: 2022 | D2: 2023 | E2: 2024 | F2: 2025
A3: LIQUIDITY RATIOS
A4: Current Ratio | B4: Mondelez. | C4: =Mondelez!L4/Mondelez!L37 -> 0.60313191 | D4: =Mondelez!M4/Mondelez!M37 -> 0.61552622 | E4: =Mondelez!N4/Mondelez!N37 -> 0.6773748 | F4: =Mondelez!O4/Mondelez!O37 -> 0.59234358
A5: Current Asset/ Current Liabilities | B5: Pepsico | C5: =Pepsico!L4/Pepsico!L40 -> 0.80414411 | D5: =Pepsico!M4/Pepsico!M40 -> 0.85158151 | E5: =Pepsico!N4/Pepsico!N40 -> 0.81893709 | F5: =Pepsico!O4/Pepsico!O40 -> 0.85303992
B6: Hershey | C6: =Hershey!L4/Hershey!L35 -> 0.80450786 | D6: =Hershey!M4/Hershey!M35 -> 0.96800607 | E6: =Hershey!N4/Hershey!N35 -> 0.95672777 | F6: =Hershey!O4/Hershey!O35 -> 1.1915747
A8: Quick Ratio | B8: Mondelez. | C8: =(Mondelez!L4-Mondelez!L12)/Mondelez!L37 -> 0.40105194 | D8: =(Mondelez!M4-Mondelez!M12)/Mondelez!M37 -> 0.42539315 | E8: =(Mondelez!N4-Mondelez!N12)/Mondelez!N37 -> 0.48161031 | F8: =(Mondelez!O4-Mondelez!O12)/Mondelez!O37 -> 0.39023052
A9: (Current Asset-Inventory)/ Current Liabilities | B9: Pepsico | C9: =(Pepsico!L4-Pepsico!L12)/Pepsico!L40 -> 0.60918424 | D9: =(Pepsico!M4-Pepsico!M12)/Pepsico!M40 -> 0.68303473 | E9: =(Pepsico!N4-Pepsico!N12)/Pepsico!N40 -> 0.65068493 | F9: =(Pepsico!O4-Pepsico!O12)/Pepsico!O40 -> 0.6746429
B10: Hershey | C10: =(Hershey!L4-Hershey!L10)/Hershey!L35 -> 0.44434098 | D10: =(Hershey!M4-Hershey!M10)/Hershey!M35 -> 0.52224839 | E10: =(Hershey!N4-Hershey!N10)/Hershey!N35 -> 0.63757887 | F10: =(Hershey!O4-Hershey!O10)/Hershey!O35 -> 0.71703837
A12: Cash Ratio | B12: Mondelez. | C12: =Mondelez!L6/Mondelez!L37 -> 0.11493635 | D12: =Mondelez!M6/Mondelez!M37 -> 0.095198022 | E12: =Mondelez!N6/Mondelez!N37 -> 0.069108394 | F12: =Mondelez!O6/Mondelez!O37 -> 0.097191731
A13: Cash and Cash Equivalents/ Current Liabilities | B13: Pepsico | C13: =Pepsico!L6/Pepsico!L40 -> 0.18495427 | D13: =Pepsico!M6/Pepsico!M40 -> 0.30685373 | E13: =Pepsico!N6/Pepsico!N40 -> 0.26969178 | F13: =Pepsico!O6/Pepsico!O40 -> 0.27954462
B14: Hershey | C14: =Hershey!L5/Hershey!L35 -> 0.14242157 | D14: =Hershey!M5/Hershey!M35 -> 0.1335954 | E14: =Hershey!N5/Hershey!N35 -> 0.18596435 | F14: =Hershey!O5/Hershey!O35 -> 0.30740072
A16: PROFITABILITY RATIOS
A17: Gross Margin | B17: Mondelez. | C17: =Mondelez!B6/Mondelez!B3 -> 0.35915672 | D17: =Mondelez!C6/Mondelez!C3 -> 0.38216348 | E17: =Mondelez!D6/Mondelez!D3 -> 0.39123515 | F17: =Mondelez!E6/Mondelez!E3 -> 0.28375328
A18: Gross Profit/ Revenue | B18: Pepsico | C18: =Pepsico!B6/Pepsico!B3 -> 0.53032688 | D18: =Pepsico!C6/Pepsico!C3 -> 0.54213904 | E18: =Pepsico!D6/Pepsico!D3 -> 0.54553966 | F18: =Pepsico!E6/Pepsico!E3 -> 0.54148523
B19: Hershey | C19: =Hershey!B6/Hershey!B3 -> 0.43177446 | D19: =Hershey!C6/Hershey!C3 -> 0.44763274 | E19: =Hershey!D6/Hershey!D3 -> 0.47319796 | F19: =Hershey!E6/Hershey!E3 -> 0.33548561
A21: Operating Profit Margin | B21: Mondelez. | C21: =Mondelez!B13/Mondelez!B3 -> 0.12052324 | D21: =Mondelez!C13/Mondelez!C3 -> 0.15579187 | E21: =Mondelez!D13/Mondelez!D3 -> 0.18289838 | F21: =Mondelez!E13/Mondelez!E3 -> 0.093935698
A22: Operating Income/ Revenue | B22: Pepsico | C22: =Pepsico!B9/Pepsico!B3 -> 0.13145893 | D22: =Pepsico!C9/Pepsico!C3 -> 0.14117043 | E22: =Pepsico!D9/Pepsico!D3 -> 0.140658 | F22: =Pepsico!E9/Pepsico!E3 -> 0.14363588
B23: Hershey | C23: =Hershey!B12/Hershey!B3 -> 0.21717172 | D23: =Hershey!C12/Hershey!C3 -> 0.22940527 | E23: =Hershey!D12/Hershey!D3 -> 0.26131033 | F23: =Hershey!E12/Hershey!E3 -> 0.12504704
A25: Net Profit Margin | B25: Mondelez. | C25: =Mondelez!B29/Mondelez!B3 -> 0.086264923 | D25: =Mondelez!C29/Mondelez!C3 -> 0.1376888 | E25: =Mondelez!D29/Mondelez!D3 -> 0.1265333 | F25: =Mondelez!E29/Mondelez!E3 -> 0.063601214
A26: Net Income/ Revenue | B26: Pepsico | C26: =Pepsico!B20/Pepsico!B3 -> 0.10313455 | D26: =Pepsico!C20/Pepsico!C3 -> 0.09920084 | E26: =Pepsico!D20/Pepsico!D3 -> 0.10427417 | F26: =Pepsico!E20/Pepsico!E3 -> 0.087729571
B27: Hershey | C27: =Hershey!B25/Hershey!B3 -> 0.15786262 | D27: =Hershey!C25/Hershey!C3 -> 0.1667522 | E27: =Hershey!D25/Hershey!D3 -> 0.19828485 | F27: =Hershey!E25/Hershey!E3 -> 0.075540155
A29: Return on Assets (ROA) | B29: Mondelez. | C29: =Mondelez!B29/Mondelez!L3 -> 0.038181026 | D29: =Mondelez!C29/Mondelez!M3 -> 0.069462537 | E29: =Mondelez!D29/Mondelez!N3 -> 0.067316817 | F29: =Mondelez!E29/Mondelez!O3 -> 0.034285954
A30: Net Income/ Total Assets | B30: Pepsico | C30: =Pepsico!B20/Pepsico!L3 -> 0.096651372 | D30: =Pepsico!C20/Pepsico!M3 -> 0.090293049 | E30: =Pepsico!D20/Pepsico!N3 -> 0.096293243 | F30: =Pepsico!E20/Pepsico!O3 -> 0.076723247
B31: Hershey | C31: =Hershey!B25/Hershey!L3 -> 0.15022779 | D31: =Hershey!C25/Hershey!M3 -> 0.15641403 | E31: =Hershey!D25/Hershey!N3 -> 0.17156583 | F31: =Hershey!E25/Hershey!O3 -> 0.064277702
A33: Return on Equity (ROE) | B33: Mondelez. | C33: =Mondelez!B29/Mondelez!L53 -> 0.10092868 | D33: =Mondelez!C29/Mondelez!M53 -> 0.17482197 | E33: =Mondelez!D29/Mondelez!N53 -> 0.17104385 | F33: =Mondelez!E29/Mondelez!O53 -> 0.0946661
A34: Net Income/ Shareholders Equity | B34: Pepsico | C34: =Pepsico!B20/Pepsico!L56 -> 0.51583396 | D34: =Pepsico!C20/Pepsico!M56 -> 0.48688094 | E34: =Pepsico!D20/Pepsico!N56 -> 0.52710363 | F34: =Pepsico!E20/Pepsico!O56 -> 0.40103178
B35: Hershey | C35: =Hershey!B25/Hershey!L53 -> 0.49849828 | D35: =Hershey!C25/Hershey!M53 -> 0.45419564 | E35: =Hershey!D25/Hershey!N53 -> 0.4711351 | F35: =Hershey!E25/Hershey!O53 -> 0.19049097
A38: SOLVENCY RATIOS
A39: Debt-to-Equity | B39: Mondelez. | C39: =Mondelez!L60/Mondelez!L53 -> 0.87098811 | D39: =Mondelez!M60/Mondelez!M53 -> 0.70313051 | E39: =Mondelez!N60/Mondelez!N53 -> 0.68150456 | F39: =Mondelez!O60/Mondelez!O53 -> 0.84214592
A40: Total Debt/ Total Equity | B40: Pepsico | C40: =Pepsico!L63/Pepsico!L56 -> 2.2899323 | D40: =Pepsico!M63/Pepsico!M56 -> 2.3963621 | E40: =Pepsico!N63/Pepsico!N56 -> 2.4736118 | F40: =Pepsico!O63/Pepsico!O56 -> 2.4286271
B41: Hershey | C41: =Hershey!L59/Hershey!L53 -> 1.5511177 | D41: =Hershey!M59/Hershey!M53 -> 1.250428 | E41: =Hershey!N59/Hershey!N53 -> 1.1554515 | F41: =Hershey!O59/Hershey!O53 -> 1.2376287
A43: Debt-to-Assets | B43: Mondelez. | C43: =Mondelez!L60/Mondelez!L3 -> 0.32949228 | D43: =Mondelez!M60/Mondelez!M3 -> 0.27937695 | E43: =Mondelez!N60/Mondelez!N3 -> 0.26821613 | F43: =Mondelez!O60/Mondelez!O3 -> 0.3050065
A44: Total Debt/ Total Asset | B44: Pepsico | C44: =Pepsico!L63/Pepsico!L3 -> 0.42906267 | D44: =Pepsico!M63/Pepsico!M3 -> 0.44441017 | E44: =Pepsico!N63/Pepsico!N3 -> 0.45188857 | F44: =Pepsico!O63/Pepsico!O3 -> 0.46463189
B45: Hershey | C45: =Hershey!L59/Hershey!L3 -> 0.4674459 | D45: =Hershey!M59/Hershey!M3 -> 0.43061727 | E45: =Hershey!N59/Hershey!N3 -> 0.42076253 | F45: =Hershey!O59/Hershey!O3 -> 0.41761524
A47: Interest Coverage (x) | B47: Mondelez. | C47: =Mondelez!B44/Mondelez!B42 -> 8.5420561 | D47: =Mondelez!C44/Mondelez!C42 -> 11.690909 | E47: =Mondelez!D44/Mondelez!D42 -> 13.324803 | F47: =Mondelez!E44/Mondelez!E42 -> 6.0317195
A48: EBIT/ Interest Expense | B48: Pepsico | C48: =Pepsico!B35/Pepsico!B33 -> 12.400426 | D48: =Pepsico!C35/Pepsico!C33 -> 14.940171 | E48: =Pepsico!D35/Pepsico!D33 -> 13.998912 | F48: =Pepsico!E35/Pepsico!E33 -> 10.138269
B49: Hershey | C49: =Hershey!B41/Hershey!B39 -> 14.684079 | D49: =Hershey!C41/Hershey!C39 -> 14.447158 | E49: =Hershey!D41/Hershey!D39 -> 15.192167 | F49: =Hershey!E41/Hershey!E39 -> 6.401137
A51: Debt to EBITDA | B51: Mondelez. | C51: =Mondelez!L60/Mondelez!B45 -> 4.9227378 | D51: =Mondelez!M60/Mondelez!C45 -> 2.6088947 | E51: =Mondelez!N60/Mondelez!D45 -> 2.2762979 | F51: =Mondelez!O60/Mondelez!E45 -> 4.3862402
A52: Total Debt/ EBITDA | B52: Pepsico | C52: =Pepsico!L63/Pepsico!B36 -> 2.6503618 | D52: =Pepsico!M63/Pepsico!C36 -> 2.8348991 | E52: =Pepsico!N63/Pepsico!D36 -> 2.6947242 | F52: =Pepsico!O63/Pepsico!E36 -> 3.2105128
...

Sheet Trend Analysis 
A1: TREND ANALYSIS | J1: TREND ANALYSIS (yoy Growth)
A2: REVENUE | J2: REVENUE
A3: Company | B3: 2022 | C3: 2023 | D3: 2024 | E3: 2025 | F3: Trend | J3: Company | K3: 2022 | L3: 2023 | M3: 2024 | N3: 2025 | O3: Average
A4: Mondelez. | B4: =Mondelez!B3 -> 31496000 | C4: =Mondelez!C3 -> 36016000 | D4: =Mondelez!D3 -> 36441000 | E4: =Mondelez!E3 -> 38537000 | F4: =E4/B4 -> 1.2235522 | J4: Mondelez. | L4: =(C4-B4)/B4 -> 0.14351029 | M4: =(D4-C4)/C4 -> 0.011800311 | N4: =(E4-D4)/D4 -> 0.057517631 | O4: =AVERAGE(L4:N4) -> 0.070942743
A5: Pepsico | B5: =Pepsico!B3 -> 86392000 | C5: =Pepsico!C3 -> 91471000 | D5: =Pepsico!D3 -> 91854000 | E5: =Pepsico!E3 -> 93925000 | F5: =E5/B5 -> 1.0871956 | J5: Pepsico | L5: =(C5-B5)/B5 -> 0.058790166 | M5: =(D5-C5)/C5 -> 0.0041871194 | N5: =(E5-D5)/D5 -> 0.02254665 | O5: =AVERAGE(L5:N5) -> 0.028507978
A6: Hershey | B6: =Hershey!B3 -> 10419294 | C6: =Hershey!C3 -> 11164992 | D6: =Hershey!D3 -> 11202263 | E6: =Hershey!E3 -> 11692576 | F6: =E6/B6 -> 1.1222042 | J6: Hershey | L6: =(C6-B6)/B6 -> 0.071568957 | M6: =(D6-C6)/C6 -> 0.0033382021 | N6: =(E6-D6)/D6 -> 0.043769103 | O6: =AVERAGE(L6:N6) -> 0.039558754
A8: NET INCOME | J8: NET INCOME
A9: Company | B9: 2022 | C9: 2023 | D9: 2024 | E9: 2025 | F9: Trend | J9: Company | K9: 2022 | L9: 2023 | M9: 2024 | N9: 2025 | O9: Average
A10: Mondelez. | B10: =Mondelez!B29 -> 2717000 | C10: =Mondelez!C29 -> 4959000 | D10: =Mondelez!D29 -> 4611000 | E10: =Mondelez!E29 -> 2451000 | F10: =E10/B10 -> 0.9020979 | J10: Mondelez. | L10: =(C10-B10)/B10 -> 0.82517483 | M10: =(D10-C10)/C10 -> -0.070175439 | N10: =(E10-D10)/D10 -> -0.46844502 | O10: =AVERAGE(L10:N10) -> 0.095518121
A11: Pepsico | B11: =Pepsico!B20 -> 8910000 | C11: =Pepsico!C20 -> 9074000 | D11: =Pepsico!D20 -> 9578000 | E11: =Pepsico!E20 -> 8240000 | F11: =E11/B11 -> 0.92480359 | J11: Pepsico | L11: =(C11-B11)/B11 -> 0.018406285 | M11: =(D11-C11)/C11 -> 0.055543311 | N11: =(E11-D11)/D11 -> -0.13969513 | O11: =AVERAGE(L11:N11) -> -0.02191518
A12: Hershey | B12: =Hershey!B25 -> 1644817 | C12: =Hershey!C25 -> 1861787 | D12: =Hershey!D25 -> 2221239 | E12: =Hershey!E25 -> 883259 | F12: =E12/B12 -> 0.5369953 | J12: Hershey | L12: =(C12-B12)/B12 -> 0.13191133 | M12: =(D12-C12)/C12 -> 0.19306827 | N12: =(E12-D12)/D12 -> -0.60235751 | O12: =AVERAGE(L12:N12) -> -0.092459303
A14: EBITDA | J14: EBITDA
A15: Company | B15: 2022 | C15: 2023 | D15: 2024 | E15: 2025 | F15: Trend | J15: Company | K15: 2022 | L15: 2023 | M15: 2024 | N15: 2025 | O15: Average
A16: Mondelez. | B16: =Mondelez!B45 -> 4763000 | C16: =Mondelez!C45 -> 7645000 | D16: =Mondelez!D45 -> 8071000 | E16: =Mondelez!E45 -> 4971000 | F16: =E16/B16 -> 1.04367 | J16: Mondelez. | L16: =(C16-B16)/B16 -> 0.60508083 | M16: =(D16-C16)/C16 -> 0.055722695 | N16: =(E16-D16)/D16 -> -0.38409119 | O16: =AVERAGE(L16:N16) -> 0.092237445
A17: Pepsico | B17: =Pepsico!B36 -> 14924000 | C17: =Pepsico!C36 -> 15754000 | D17: =Pepsico!D36 -> 16680000 | E17: =Pepsico!E36 -> 15543000 | F17: =E17/B17 -> 1.0414768 | J17: Pepsico | L17: =(C17-B17)/B17 -> 0.055615117 | M17: =(D17-C17)/C17 -> 0.058778723 | N17: =(E17-D17)/D17 -> -0.068165468 | O17: =AVERAGE(L17:N17) -> 0.015409457
A18: Hershey | B18: =Hershey!B42 -> 2436125 | C18: =Hershey!C42 -> 2753190 | D18: =Hershey!D42 -> 3103508 | E18: =Hershey!E42 -> 1942715 | F18: =E18/B18 -> 0.79746113 | J18: Hershey | L18: =(C18-B18)/B18 -> 0.13015137 | M18: =(D18-C18)/C18 -> 0.12724076 | N18: =(E18-D18)/D18 -> -0.3740261 | O18: =AVERAGE(L18:N18) -> -0.03887799
A20: TOTAL ASSETS | J20: TOTAL ASSETS
A21: Company | B21: 2022 | C21: 2023 | D21: 2024 | E21: 2025 | F21: Trend | J21: Company | K21: 2022 | L21: 2023 | M21: 2024 | N21: 2025 | O21: Average
A22: Mondelez. | B22: =Mondelez!L3 -> 71161000 | C22: =Mondelez!M3 -> 71391000 | D22: =Mondelez!N3 -> 68497000 | E22: =Mondelez!O3 -> 71487000 | F22: =E22/B22 -> 1.0045812 | J22: Mondelez. | L22: =(C22-B22)/B22 -> 0.0032321075 | M22: =(D22-C22)/C22 -> -0.040537323 | N22: =(E22-D22)/D22 -> 0.043651547 | O22: =AVERAGE(L22:N22) -> 0.0021154439
A23: Pepsico | B23: =Pepsico!L3 -> 92187000 | C23: =Pepsico!M3 -> 100495000 | D23: =Pepsico!N3 -> 99467000 | E23: =Pepsico!O3 -> 107399000 | F23: =E23/B23 -> 1.1650124 | J23: Pepsico | L23: =(C23-B23)/B23 -> 0.090121167 | M23: =(D23-C23)/C23 -> -0.010229365 | N23: =(E23-D23)/D23 -> 0.079745041 | O23: =AVERAGE(L23:N23) -> 0.053212281
A24: Hershey | B24: =Hershey!L3 -> 10948820 | C24: =Hershey!M3 -> 11902941 | D24: =Hershey!N3 -> 12946861 | E24: =Hershey!O3 -> 13741297 | F24: =E24/B24 -> 1.2550482 | J24: Hershey | L24: =(C24-B24)/B24 -> 0.087143729 | M24: =(D24-C24)/C24 -> 0.087702695 | N24: =(E24-D24)/D24 -> 0.061361283 | O24: =AVERAGE(L24:N24) -> 0.078735902
A26: TOTAL LIABILITIES | J26: TOTAL LIABILITIES
A27: Company | B27: 2022 | C27: 2023 | D27: 2024 | E27: 2025 | F27: Trend | J27: Company | K27: 2022 | L27: 2023 | M27: 2024 | N27: 2025 | O27: Average
A28: Mondelez. | B28: =Mondelez!L36 -> 44241000 | C28: =Mondelez!M36 -> 43025000 | D28: =Mondelez!N36 -> 41539000 | E28: =Mondelez!O36 -> 45596000 | F28: =E28/B28 -> 1.0306277 | J28: Mondelez. | L28: =(C28-B28)/B28 -> -0.027485816 | M28: =(D28-C28)/C28 -> -0.034538059 | N28: =(E28-D28)/D28 -> 0.097667252 | O28: =AVERAGE(L28:N28) -> 0.011881126
A29: Pepsico | B29: =Pepsico!L39 -> 74914000 | C29: =Pepsico!M39 -> 81858000 | D29: =Pepsico!N39 -> 81296000 | E29: =Pepsico!O39 -> 86852000 | F29: =E29/B29 -> 1.1593561 | J29: Pepsico | L29: =(C29-B29)/B29 -> 0.092692955 | M29: =(D29-C29)/C29 -> -0.0068655477 | N29: =(E29-D29)/D29 -> 0.068342846 | O29: =AVERAGE(L29:N29) -> 0.051390084
A30: Hershey | B30: =Hershey!L34 -> 7649276 | C30: =Hershey!M34 -> 7803855 | D30: =Hershey!N34 -> 8232207 | E30: =Hershey!O34 -> 9104547 | F30: =E30/B30 -> 1.1902495 | J30: Hershey | L30: =(C30-B30)/B30 -> 0.020208318 | M30: =(D30-C30)/C30 -> 0.054889795 | N30: =(E30-D30)/D30 -> 0.10596672 | O30: =AVERAGE(L30:N30) -> 0.060354945
A32: Profit(Net Income ) | J32: Profit(Net Income )
A33: Company | B33: 2022 | C33: 2023 | D33: 2024 | E33: 2025 | F33: Trend | J33: Company | K33: 2022 | L33: 2023 | M33: 2024 | N33: 2025 | O33: Average
A34: Mondelez. | B34: =Mondelez!B29 -> 2717000 | C34: =Mondelez!C29 -> 4959000 | D34: =Mondelez!D29 -> 4611000 | E34: =Mondelez!E29 -> 2451000 | F34: =E34/B34 -> 0.9020979 | J34: Mondelez. | L34: =(C34-B34)/B34 -> 0.82517483 | M34: =(D34-C34)/C34 -> -0.070175439 | N34: =(E34-D34)/D34 -> -0.46844502 | O34: =AVERAGE(L34:N34) -> 0.095518121
A35: Pepsico | B35: =Pepsico!B20 -> 8910000 | C35: =Pepsico!C20 -> 9074000 | D35: =Pepsico!D20 -> 9578000 | E35: =Pepsico!E20 -> 8240000 | F35: =E35/B35 -> 0.92480359 | J35: Pepsico | L35: =(C35-B35)/B35 -> 0.018406285 | M35: =(D35-C35)/C35 -> 0.055543311 | N35: =(E35-D35)/D35 -> -0.13969513 | O35: =AVERAGE(L35:N35) -> -0.02191518
A36: Hershey | B36: =Hershey!B25 -> 1644817 | C36: =Hershey!C25 -> 1861787 | D36: =Hershey!D25 -> 2221239 | E36: =Hershey!E25 -> 883259 | F36: =E36/B36 -> 0.5369953 | J36: Hershey | L36: =(C36-B36)/B36 -> 0.13191133 | M36: =(D36-C36)/C36 -> 0.19306827 | N36: =(E36-D36)/D36 -> -0.60235751 | O36: =AVERAGE(L36:N36) -> -0.092459303
A38: Cash Flow from Operations | J38: Cash Flow from Operations
A39: Company | B39: 2022 | C39: 2023 | D39: 2024 | E39: 2025 | F39: Trend | J39: Company | K39: 2022 | L39: 2023 | M39: 2024 | N39: 2025 | O39: Average
A40: Mondelez. | B40: =Mondelez!V3 -> 3908000 | C40: =Mondelez!W3 -> 4714000 | D40: =Mondelez!X3 -> 4910000 | E40: =Mondelez!Y3 -> 4514000 | F40: =E40/B40 -> 1.1550665 | J40: Mondelez. | L40: =(C40-B40)/B40 -> 0.2062436 | M40: =(D40-C40)/C40 -> 0.041578277 | N40: =(E40-D40)/D40 -> -0.080651731 | O40: =AVERAGE(L40:N40) -> 0.055723383
A41: Pepsico | B41: =Pepsico!V3 -> 10811000 | C41: =Pepsico!W3 -> 13442000 | D41: =Pepsico!X3 -> 12507000 | E41: =Pepsico!Y3 -> 12087000 | F41: =E41/B41 -> 1.1180279 | J41: Pepsico | L41: =(C41-B41)/B41 -> 0.24336324 | M41: =(D41-C41)/C41 -> -0.069558101 | N41: =(E41-D41)/D41 -> -0.033581195 | O41: =AVERAGE(L41:N41) -> 0.046741315
A42: Hershey | B42: =Hershey!V3 -> 2327837 | C42: =Hershey!W3 -> 2323190 | D42: =Hershey!X3 -> 2531596 | E42: =Hershey!Y3 -> 2277367 | F42: =E42/B42 -> 0.97831893 | J42: Hershey | L42: =(C42-B42)/B42 -> -0.0019962738 | M42: =(D42-C42)/C42 -> 0.089706826 | N42: =(E42-D42)/D42 -> -0.10042242 | O42: =AVERAGE(L42:N42) -> -0.0042372898
A44: Cash Flow from investing Activities | J44: Cash Flow from investing Activities
A45: Company | B45: 2022 | C45: 2023 | D45: 2024 | E45: 2025 | F45: Trend | J45: Company | K45: 2022 | L45: 2023 | M45: 2024 | N45: 2025 | O45: Average
A46: Mondelez. | B46: =Mondelez!V27 -> -4888000 | C46: =Mondelez!W27 -> 2812000 | D46: =Mondelez!X27 -> 526000 | E46: =Mondelez!Y27 -> -1196000 | F46: =E46/B46 -> 0.24468085 | J46: Mondelez. | L46: =(C46-B46)/B46 -> -1.5752864 | M46: =(D46-C46)/C46 -> -0.81294452 | N46: =(E46-D46)/D46 -> -3.2737643 | O46: =AVERAGE(L46:N46) -> -1.8873317
A47: Pepsico | B47: =Pepsico!V27 -> -2430000 | C47: =Pepsico!W27 -> -5495000 | D47: =Pepsico!X27 -> -5472000 | E47: =Pepsico!Y27 -> -6879000 | F47: =E47/B47 -> 2.8308642 | J47: Pepsico | L47: =(C47-B47)/B47 -> 1.2613169 | M47: =(D47-C47)/C47 -> -0.0041856233 | N47: =(E47-D47)/D47 -> 0.25712719 | O47: =AVERAGE(L47:N47) -> 0.50475281
...

Sheet Financial Projections
A1: FINANCIAL PROJECTIONS
A2: PROJECTION ASSUMPTIONS
A3: Assumption | B3: Mondelez | C3: PepsiCo | D3: Hershey
A4: Revenue Growth Rate (Annual) | B4: 0.05 | C4: 0.03 | D4: 0.04
A5: COGS % of Revenue | B5: 0.646 | C5: 0.46 | D5: 0.578
A6: Operating Margin | B6: 0.138 | C6: 0.139 | D6: 0.208
A7: Net Profit Margin | B7: 0.104 | C7: 0.099 | D7: 0.15
A8: D&A % of Revenue (est.) | B8: 0.035 | C8: 0.041 | D8: 0.039
A9: Total Assets / Revenue Ratio (x) | B9: 1.99 | C9: 1.1 | D9: 1.11
A11: PROJECTED INCOME STATEMENT
B12: Mondelez | F12: PepsiCo | J12: Hershey
A13: Particulars | B13: FY2026 | C13: FY2027 | D13: FY2028 | F13: FY2026 | G13: FY2027 | H13: FY2028 | J13: FY2026 | K13: FY2027 | L13: FY2028
A14: Total Revenue | B14: =Mondelez!E3*(1+$B$4) -> 40463850 | C14: =B14*(1+$B$4) -> 42487042 | D14: =C14*(1+$B$4) -> 44611395 | F14: =Pepsico!E3*(1+$C$4) -> 96742750 | G14: =F14*(1+$C$4) -> 99645032 | H14: =G14*(1+$C$4) -> 1.0263438e+08 | J14: =Hershey!E3*(1+$D$4) -> 12160279 | K14: =J14*(1+$D$4) -> 12646690 | L14: =K14*(1+$D$4) -> 13152558
A15: Cost of Revenue | B15: =B14*$B$5 -> 26139647 | C15: =C14*$B$5 -> 27446629 | D15: =D14*$B$5 -> 28818961 | F15: =F14*$C$5 -> 44501665 | G15: =G14*$C$5 -> 45836715 | H15: =H14*$C$5 -> 47211816 | J15: =J14*$D$5 -> 7028641.3 | K15: =K14*$D$5 -> 7309786.9 | L15: =L14*$D$5 -> 7602178.4
A16: Gross Profit | B16: =B14-B15 -> 14324203 | C16: =C14-C15 -> 15040413 | D16: =D14-D15 -> 15792434 | F16: =F14-F15 -> 52241085 | G16: =G14-G15 -> 53808318 | H16: =H14-H15 -> 55422567 | J16: =J14-J15 -> 5131637.8 | K16: =K14-K15 -> 5336903.3 | L16: =L14-L15 -> 5550379.4
A17: Operating Income | B17: =B14*$B$6 -> 5584011.3 | C17: =C14*$B$6 -> 5863211.9 | D17: =D14*$B$6 -> 6156372.5 | F17: =F14*$C$6 -> 13447242 | G17: =G14*$C$6 -> 13850660 | H17: =H14*$C$6 -> 14266179 | J17: =J14*$D$6 -> 2529338 | K17: =K14*$D$6 -> 2630511.6 | L17: =L14*$D$6 -> 2735732
A18: Net Income | B18: =B14*$B$7 -> 4208240.4 | C18: =C14*$B$7 -> 4418652.4 | D18: =D14*$B$7 -> 4639585 | F18: =F14*$C$7 -> 9577532.2 | G18: =G14*$C$7 -> 9864858.2 | H18: =H14*$C$7 -> 10160804 | J18: =J14*$D$7 -> 1824041.9 | K18: =K14*$D$7 -> 1897003.5 | L18: =L14*$D$7 -> 1972883.7
A19: EBITDA | B19: =B17+B14*$B$8 -> 7000246.1 | C19: =C17+C14*$B$8 -> 7350258.4 | D19: =D17+D14*$B$8 -> 7717771.3 | F19: =F17+F14*$C$8 -> 17413695 | G19: =G17+G14*$C$8 -> 17936106 | H19: =H17+H14*$C$8 -> 18474189 | J19: =J17+J14*$D$8 -> 3003588.9 | K19: =K17+K14*$D$8 -> 3123732.5 | L19: =L17+L14*$D$8 -> 3248681.8
A22: PROJECTED BALANCE SHEET
B23: Mondelez | F23: PepsiCo | J23: Hershey
A24: Particulars | B24: FY2026 | C24: FY2027 | D24: FY2028 | F24: FY2026 | G24: FY2027 | H24: FY2028 | J24: FY2026 | K24: FY2027 | L24: FY2028
A25: Total Assets | B25: =B14*$B$9 -> 80523062 | C25: =C14*$B$9 -> 84549215 | D25: =D14*$B$9 -> 88776675 | F25: =F14*$C$9 -> 1.0641703e+08 | G25: =G14*$C$9 -> 1.0960954e+08 | H25: =H14*$C$9 -> 1.1289782e+08 | J25: =J14*$D$9 -> 13497910 | K25: =K14*$D$9 -> 14037826 | L25: =L14*$D$9 -> 14599339
A26: Total Equity | B26: =Mondelez!O53+B18 -> 30099240 | C26: =B26+C18 -> 34517893 | D26: =C26+D18 -> 39157478 | F26: =Pepsico!O56+F18 -> 30124532 | G26: =F26+G18 -> 39989390 | H26: =G26+H18 -> 50150194 | J26: =Hershey!O53+J18 -> 6460791.9 | K26: =J26+K18 -> 8357795.4 | L26: =K26+L18 -> 10330679
A27: Total Liabilities | B27: =B25-B26 -> 50423821 | C27: =C25-C26 -> 50031322 | D27: =D25-D26 -> 49619197 | F27: =F25-F26 -> 76292493 | G27: =G25-G26 -> 69620145 | H27: =H25-H26 -> 62747627 | J27: =J25-J26 -> 7037117.9 | K27: =K25-K26 -> 5680030.7 | L27: =L25-L26 -> 4268660.1
